[2024-04-26T17:23:09.392+0000] {local_task_job_runner.py:120} INFO - ::group::Pre task execution logs
[2024-04-26T17:23:09.420+0000] {taskinstance.py:2073} INFO - Dependencies all met for dep_context=non-requeueable deps ti=<TaskInstance: air_quality_pipeline.etl.transform backfill__2024-04-03T22:00:00+00:00 [queued]>
[2024-04-26T17:23:09.427+0000] {taskinstance.py:2073} INFO - Dependencies all met for dep_context=requeueable deps ti=<TaskInstance: air_quality_pipeline.etl.transform backfill__2024-04-03T22:00:00+00:00 [queued]>
[2024-04-26T17:23:09.427+0000] {taskinstance.py:2303} INFO - Starting attempt 1 of 2
[2024-04-26T17:23:09.439+0000] {taskinstance.py:2327} INFO - Executing <Task(PythonOperator): etl.transform> on 2024-04-03 22:00:00+00:00
[2024-04-26T17:23:09.451+0000] {logging_mixin.py:188} WARNING - /home/***/.local/lib/python3.12/site-packages/***/task/task_runner/standard_task_runner.py:61 DeprecationWarning: This process (pid=824) is multi-threaded, use of fork() may lead to deadlocks in the child.
[2024-04-26T17:23:09.451+0000] {standard_task_runner.py:63} INFO - Started process 828 to run task
[2024-04-26T17:23:09.451+0000] {standard_task_runner.py:90} INFO - Running: ['***', 'tasks', 'run', 'air_quality_pipeline', 'etl.transform', 'backfill__2024-04-03T22:00:00+00:00', '--job-id', '327', '--pool', 'default_pool', '--raw', '--subdir', 'DAGS_FOLDER/air_quality/air_quality_dag.py', '--cfg-path', '/tmp/tmp94l4g_lz']
[2024-04-26T17:23:09.453+0000] {standard_task_runner.py:91} INFO - Job 327: Subtask etl.transform
[2024-04-26T17:23:09.490+0000] {task_command.py:426} INFO - Running <TaskInstance: air_quality_pipeline.etl.transform backfill__2024-04-03T22:00:00+00:00 [running]> on host 4718ecf2379c
[2024-04-26T17:23:09.556+0000] {taskinstance.py:2644} INFO - Exporting env vars: AIRFLOW_CTX_DAG_OWNER='***' AIRFLOW_CTX_DAG_ID='air_quality_pipeline' AIRFLOW_CTX_TASK_ID='etl.transform' AIRFLOW_CTX_EXECUTION_DATE='2024-04-03T22:00:00+00:00' AIRFLOW_CTX_TRY_NUMBER='1' AIRFLOW_CTX_DAG_RUN_ID='backfill__2024-04-03T22:00:00+00:00'
[2024-04-26T17:23:09.556+0000] {taskinstance.py:430} INFO - ::endgroup::
[2024-04-26T17:23:09.565+0000] {tasks.py:52} INFO - Transforming location data...
[2024-04-26T17:23:09.574+0000] {LocationConnector.py:104} ERROR - Error transforming DataFrame: 'NoneType' object has no attribute 'split'
[2024-04-26T17:23:09.575+0000] {tasks.py:54} INFO - Location data transformation complete.
[2024-04-26T17:23:09.575+0000] {tasks.py:57} INFO - Transforming air quality data...
[2024-04-26T17:23:09.579+0000] {AirQualityConnector.py:101} INFO - Successfully transformed DataFrame
[2024-04-26T17:23:09.579+0000] {AirQualityConnector.py:102} INFO - Shape of transformed DataFrame: (46, 11)
[2024-04-26T17:23:09.579+0000] {tasks.py:59} INFO - Air quality data transformation complete.
[2024-04-26T17:23:09.579+0000] {tasks.py:62} INFO - Merging location and air quality data...
[2024-04-26T17:23:09.580+0000] {taskinstance.py:441} INFO - ::group::Post task execution logs
[2024-04-26T17:23:09.580+0000] {taskinstance.py:2890} ERROR - Task failed with exception
Traceback (most recent call last):
  File "/home/airflow/.local/lib/python3.12/site-packages/airflow/models/taskinstance.py", line 465, in _execute_task
    result = _execute_callable(context=context, **execute_callable_kwargs)
             ^^^^^^^^^^^^^^^^^^^^^^^^^^^^^^^^^^^^^^^^^^^^^^^^^^^^^^^^^^^^^
  File "/home/airflow/.local/lib/python3.12/site-packages/airflow/models/taskinstance.py", line 432, in _execute_callable
    return execute_callable(context=context, **execute_callable_kwargs)
           ^^^^^^^^^^^^^^^^^^^^^^^^^^^^^^^^^^^^^^^^^^^^^^^^^^^^^^^^^^^^
  File "/home/airflow/.local/lib/python3.12/site-packages/airflow/models/baseoperator.py", line 400, in wrapper
    return func(self, *args, **kwargs)
           ^^^^^^^^^^^^^^^^^^^^^^^^^^^
  File "/home/airflow/.local/lib/python3.12/site-packages/airflow/operators/python.py", line 235, in execute
    return_value = self.execute_callable()
                   ^^^^^^^^^^^^^^^^^^^^^^^
  File "/home/airflow/.local/lib/python3.12/site-packages/airflow/operators/python.py", line 252, in execute_callable
    return self.python_callable(*self.op_args, **self.op_kwargs)
           ^^^^^^^^^^^^^^^^^^^^^^^^^^^^^^^^^^^^^^^^^^^^^^^^^^^^^
  File "/opt/airflow/dags/air_quality/tasks.py", line 63, in transform_data
    merged_data = pd.merge(transformed_location_data, transformed_air_quality_data, on="latitude", how="inner")
                  ^^^^^^^^^^^^^^^^^^^^^^^^^^^^^^^^^^^^^^^^^^^^^^^^^^^^^^^^^^^^^^^^^^^^^^^^^^^^^^^^^^^^^^^^^^^^^
  File "/home/airflow/.local/lib/python3.12/site-packages/pandas/core/reshape/merge.py", line 169, in merge
    op = _MergeOperation(
         ^^^^^^^^^^^^^^^^
  File "/home/airflow/.local/lib/python3.12/site-packages/pandas/core/reshape/merge.py", line 791, in __init__
    ) = self._get_merge_keys()
        ^^^^^^^^^^^^^^^^^^^^^^
  File "/home/airflow/.local/lib/python3.12/site-packages/pandas/core/reshape/merge.py", line 1287, in _get_merge_keys
    left_keys.append(left._get_label_or_level_values(lk))
                     ^^^^^^^^^^^^^^^^^^^^^^^^^^^^^^^^^^^
  File "/home/airflow/.local/lib/python3.12/site-packages/pandas/core/generic.py", line 1844, in _get_label_or_level_values
    raise KeyError(key)
KeyError: 'latitude'
[2024-04-26T17:23:09.592+0000] {taskinstance.py:1205} INFO - Marking task as UP_FOR_RETRY. dag_id=air_quality_pipeline, task_id=etl.transform, execution_date=20240403T220000, start_date=20240426T172309, end_date=20240426T172309
[2024-04-26T17:23:09.599+0000] {standard_task_runner.py:110} ERROR - Failed to execute job 327 for task etl.transform ('latitude'; 828)
[2024-04-26T17:23:09.624+0000] {local_task_job_runner.py:240} INFO - Task exited with return code 1
[2024-04-26T17:23:09.643+0000] {taskinstance.py:3482} INFO - 0 downstream tasks scheduled from follow-on schedule check
[2024-04-26T17:23:09.645+0000] {local_task_job_runner.py:222} INFO - ::endgroup::
