[2024-04-23T21:05:39.066+0000] {local_task_job_runner.py:120} INFO - ::group::Pre task execution logs
[2024-04-23T21:05:39.087+0000] {taskinstance.py:2073} INFO - Dependencies all met for dep_context=non-requeueable deps ti=<TaskInstance: pipeline.trasform manual__2024-04-23T21:05:11.136032+00:00 [queued]>
[2024-04-23T21:05:39.093+0000] {taskinstance.py:2073} INFO - Dependencies all met for dep_context=requeueable deps ti=<TaskInstance: pipeline.trasform manual__2024-04-23T21:05:11.136032+00:00 [queued]>
[2024-04-23T21:05:39.093+0000] {taskinstance.py:2303} INFO - Starting attempt 1 of 1
[2024-04-23T21:05:39.102+0000] {taskinstance.py:2327} INFO - Executing <Task(PythonOperator): trasform> on 2024-04-23 21:05:11.136032+00:00
[2024-04-23T21:05:39.110+0000] {standard_task_runner.py:90} INFO - Running: ['***', 'tasks', 'run', 'pipeline', 'trasform', 'manual__2024-04-23T21:05:11.136032+00:00', '--job-id', '41', '--raw', '--subdir', 'DAGS_FOLDER/air_quality/air_quality_dag.py', '--cfg-path', '/tmp/tmpl7sftbca']
[2024-04-23T21:05:39.112+0000] {standard_task_runner.py:91} INFO - Job 41: Subtask trasform
[2024-04-23T21:05:39.114+0000] {logging_mixin.py:188} WARNING - /home/***/.local/lib/python3.12/site-packages/***/task/task_runner/standard_task_runner.py:61 DeprecationWarning: This process (pid=1444) is multi-threaded, use of fork() may lead to deadlocks in the child.
[2024-04-23T21:05:39.115+0000] {standard_task_runner.py:63} INFO - Started process 1446 to run task
[2024-04-23T21:05:39.144+0000] {task_command.py:426} INFO - Running <TaskInstance: pipeline.trasform manual__2024-04-23T21:05:11.136032+00:00 [running]> on host 1b9b58bb0dc3
[2024-04-23T21:05:39.201+0000] {taskinstance.py:2644} INFO - Exporting env vars: AIRFLOW_CTX_DAG_OWNER='***' AIRFLOW_CTX_DAG_ID='pipeline' AIRFLOW_CTX_TASK_ID='trasform' AIRFLOW_CTX_EXECUTION_DATE='2024-04-23T21:05:11.136032+00:00' AIRFLOW_CTX_TRY_NUMBER='1' AIRFLOW_CTX_DAG_RUN_ID='manual__2024-04-23T21:05:11.136032+00:00'
[2024-04-23T21:05:39.202+0000] {taskinstance.py:430} INFO - ::endgroup::
[2024-04-23T21:05:39.226+0000] {taskinstance.py:441} INFO - ::group::Post task execution logs
[2024-04-23T21:05:39.227+0000] {taskinstance.py:2890} ERROR - Task failed with exception
Traceback (most recent call last):
  File "/home/airflow/.local/lib/python3.12/site-packages/airflow/models/taskinstance.py", line 465, in _execute_task
    result = _execute_callable(context=context, **execute_callable_kwargs)
             ^^^^^^^^^^^^^^^^^^^^^^^^^^^^^^^^^^^^^^^^^^^^^^^^^^^^^^^^^^^^^
  File "/home/airflow/.local/lib/python3.12/site-packages/airflow/models/taskinstance.py", line 432, in _execute_callable
    return execute_callable(context=context, **execute_callable_kwargs)
           ^^^^^^^^^^^^^^^^^^^^^^^^^^^^^^^^^^^^^^^^^^^^^^^^^^^^^^^^^^^^
  File "/home/airflow/.local/lib/python3.12/site-packages/airflow/models/baseoperator.py", line 400, in wrapper
    return func(self, *args, **kwargs)
           ^^^^^^^^^^^^^^^^^^^^^^^^^^^
  File "/home/airflow/.local/lib/python3.12/site-packages/airflow/operators/python.py", line 235, in execute
    return_value = self.execute_callable()
                   ^^^^^^^^^^^^^^^^^^^^^^^
  File "/home/airflow/.local/lib/python3.12/site-packages/airflow/operators/python.py", line 252, in execute_callable
    return self.python_callable(*self.op_args, **self.op_kwargs)
           ^^^^^^^^^^^^^^^^^^^^^^^^^^^^^^^^^^^^^^^^^^^^^^^^^^^^^
  File "/opt/airflow/dags/air_quality/tasks.py", line 17, in trasform
    df_air = connex.transform()
             ^^^^^^^^^^^^^^^^^^
  File "/opt/airflow/src/ConnectorAirQuality.py", line 62, in transform
    df_air.columns = LIST_NOMBRE_COLUMNAS
    ^^^^^^^^^^^^^^
  File "/home/airflow/.local/lib/python3.12/site-packages/pandas/core/generic.py", line 6218, in __setattr__
    return object.__setattr__(self, name, value)
           ^^^^^^^^^^^^^^^^^^^^^^^^^^^^^^^^^^^^^
  File "properties.pyx", line 69, in pandas._libs.properties.AxisProperty.__set__
  File "/home/airflow/.local/lib/python3.12/site-packages/pandas/core/generic.py", line 767, in _set_axis
    self._mgr.set_axis(axis, labels)
  File "/home/airflow/.local/lib/python3.12/site-packages/pandas/core/internals/managers.py", line 227, in set_axis
    self._validate_set_axis(axis, new_labels)
  File "/home/airflow/.local/lib/python3.12/site-packages/pandas/core/internals/base.py", line 85, in _validate_set_axis
    raise ValueError(
ValueError: Length mismatch: Expected axis has 11 elements, new values have 12 elements
[2024-04-23T21:05:39.239+0000] {taskinstance.py:1205} INFO - Marking task as FAILED. dag_id=pipeline, task_id=trasform, execution_date=20240423T210511, start_date=20240423T210539, end_date=20240423T210539
[2024-04-23T21:05:39.247+0000] {standard_task_runner.py:110} ERROR - Failed to execute job 41 for task trasform (Length mismatch: Expected axis has 11 elements, new values have 12 elements; 1446)
[2024-04-23T21:05:39.287+0000] {local_task_job_runner.py:240} INFO - Task exited with return code 1
[2024-04-23T21:05:39.302+0000] {taskinstance.py:3482} INFO - 0 downstream tasks scheduled from follow-on schedule check
[2024-04-23T21:05:39.305+0000] {local_task_job_runner.py:222} INFO - ::endgroup::
