[2024-04-23T23:27:39.253+0000] {local_task_job_runner.py:120} INFO - ::group::Pre task execution logs
[2024-04-23T23:27:39.275+0000] {taskinstance.py:2073} INFO - Dependencies all met for dep_context=non-requeueable deps ti=<TaskInstance: pipeline.transform manual__2024-04-23T23:06:35.131251+00:00 [queued]>
[2024-04-23T23:27:39.399+0000] {taskinstance.py:2073} INFO - Dependencies all met for dep_context=requeueable deps ti=<TaskInstance: pipeline.transform manual__2024-04-23T23:06:35.131251+00:00 [queued]>
[2024-04-23T23:27:39.399+0000] {taskinstance.py:2303} INFO - Starting attempt 3 of 3
[2024-04-23T23:27:39.407+0000] {taskinstance.py:2327} INFO - Executing <Task(PythonOperator): transform> on 2024-04-23 23:06:35.131251+00:00
[2024-04-23T23:27:39.418+0000] {logging_mixin.py:188} WARNING - /home/***/.local/lib/python3.12/site-packages/***/task/task_runner/standard_task_runner.py:61 DeprecationWarning: This process (pid=714) is multi-threaded, use of fork() may lead to deadlocks in the child.
[2024-04-23T23:27:39.418+0000] {standard_task_runner.py:63} INFO - Started process 716 to run task
[2024-04-23T23:27:39.417+0000] {standard_task_runner.py:90} INFO - Running: ['***', 'tasks', 'run', 'pipeline', 'transform', 'manual__2024-04-23T23:06:35.131251+00:00', '--job-id', '59', '--raw', '--subdir', 'DAGS_FOLDER/air_quality/air_quality_dag.py', '--cfg-path', '/tmp/tmpyc5y30gt']
[2024-04-23T23:27:39.419+0000] {standard_task_runner.py:91} INFO - Job 59: Subtask transform
[2024-04-23T23:27:39.450+0000] {task_command.py:426} INFO - Running <TaskInstance: pipeline.transform manual__2024-04-23T23:06:35.131251+00:00 [running]> on host 8e318e51dc55
[2024-04-23T23:27:39.511+0000] {taskinstance.py:2644} INFO - Exporting env vars: AIRFLOW_CTX_DAG_OWNER='***' AIRFLOW_CTX_DAG_ID='pipeline' AIRFLOW_CTX_TASK_ID='transform' AIRFLOW_CTX_EXECUTION_DATE='2024-04-23T23:06:35.131251+00:00' AIRFLOW_CTX_TRY_NUMBER='3' AIRFLOW_CTX_DAG_RUN_ID='manual__2024-04-23T23:06:35.131251+00:00'
[2024-04-23T23:27:39.512+0000] {taskinstance.py:430} INFO - ::endgroup::
[2024-04-23T23:27:39.532+0000] {taskinstance.py:441} INFO - ::group::Post task execution logs
[2024-04-23T23:27:39.533+0000] {taskinstance.py:2890} ERROR - Task failed with exception
Traceback (most recent call last):
  File "/home/airflow/.local/lib/python3.12/site-packages/airflow/models/taskinstance.py", line 465, in _execute_task
    result = _execute_callable(context=context, **execute_callable_kwargs)
             ^^^^^^^^^^^^^^^^^^^^^^^^^^^^^^^^^^^^^^^^^^^^^^^^^^^^^^^^^^^^^
  File "/home/airflow/.local/lib/python3.12/site-packages/airflow/models/taskinstance.py", line 432, in _execute_callable
    return execute_callable(context=context, **execute_callable_kwargs)
           ^^^^^^^^^^^^^^^^^^^^^^^^^^^^^^^^^^^^^^^^^^^^^^^^^^^^^^^^^^^^
  File "/home/airflow/.local/lib/python3.12/site-packages/airflow/models/baseoperator.py", line 400, in wrapper
    return func(self, *args, **kwargs)
           ^^^^^^^^^^^^^^^^^^^^^^^^^^^
  File "/home/airflow/.local/lib/python3.12/site-packages/airflow/operators/python.py", line 235, in execute
    return_value = self.execute_callable()
                   ^^^^^^^^^^^^^^^^^^^^^^^
  File "/home/airflow/.local/lib/python3.12/site-packages/airflow/operators/python.py", line 252, in execute_callable
    return self.python_callable(*self.op_args, **self.op_kwargs)
           ^^^^^^^^^^^^^^^^^^^^^^^^^^^^^^^^^^^^^^^^^^^^^^^^^^^^^
  File "/opt/airflow/dags/air_quality/tasks.py", line 33, in transform
    df_location_transformed = location_connector.transform_location()
                              ^^^^^^^^^^^^^^^^^^^^^^^^^^^^^^^^^^^^^^^
  File "/opt/airflow/src/LocationConnector.py", line 97, in transform_location
    df_location.columns = LIST_COLUMN_NAMES_LOCATION
    ^^^^^^^^^^^^^^^^^^^
  File "/home/airflow/.local/lib/python3.12/site-packages/pandas/core/generic.py", line 6218, in __setattr__
    return object.__setattr__(self, name, value)
           ^^^^^^^^^^^^^^^^^^^^^^^^^^^^^^^^^^^^^
  File "properties.pyx", line 69, in pandas._libs.properties.AxisProperty.__set__
  File "/home/airflow/.local/lib/python3.12/site-packages/pandas/core/generic.py", line 767, in _set_axis
    self._mgr.set_axis(axis, labels)
  File "/home/airflow/.local/lib/python3.12/site-packages/pandas/core/internals/managers.py", line 227, in set_axis
    self._validate_set_axis(axis, new_labels)
  File "/home/airflow/.local/lib/python3.12/site-packages/pandas/core/internals/base.py", line 85, in _validate_set_axis
    raise ValueError(
ValueError: Length mismatch: Expected axis has 8 elements, new values have 7 elements
[2024-04-23T23:27:39.542+0000] {taskinstance.py:1205} INFO - Marking task as FAILED. dag_id=pipeline, task_id=transform, execution_date=20240423T230635, start_date=20240423T232739, end_date=20240423T232739
[2024-04-23T23:27:39.548+0000] {standard_task_runner.py:110} ERROR - Failed to execute job 59 for task transform (Length mismatch: Expected axis has 8 elements, new values have 7 elements; 716)
[2024-04-23T23:27:39.591+0000] {local_task_job_runner.py:240} INFO - Task exited with return code 1
[2024-04-23T23:27:39.606+0000] {taskinstance.py:3482} INFO - 0 downstream tasks scheduled from follow-on schedule check
[2024-04-23T23:27:39.610+0000] {local_task_job_runner.py:222} INFO - ::endgroup::
