[2024-04-23T23:31:35.855+0000] {local_task_job_runner.py:120} INFO - ::group::Pre task execution logs
[2024-04-23T23:31:35.878+0000] {taskinstance.py:2073} INFO - Dependencies all met for dep_context=non-requeueable deps ti=<TaskInstance: pipeline.transform manual__2024-04-23T23:06:35.131251+00:00 [queued]>
[2024-04-23T23:31:36.005+0000] {taskinstance.py:2073} INFO - Dependencies all met for dep_context=requeueable deps ti=<TaskInstance: pipeline.transform manual__2024-04-23T23:06:35.131251+00:00 [queued]>
[2024-04-23T23:31:36.006+0000] {taskinstance.py:2303} INFO - Starting attempt 5 of 5
[2024-04-23T23:31:36.013+0000] {taskinstance.py:2327} INFO - Executing <Task(PythonOperator): transform> on 2024-04-23 23:06:35.131251+00:00
[2024-04-23T23:31:36.024+0000] {logging_mixin.py:188} WARNING - /home/***/.local/lib/python3.12/site-packages/***/task/task_runner/standard_task_runner.py:61 DeprecationWarning: This process (pid=816) is multi-threaded, use of fork() may lead to deadlocks in the child.
[2024-04-23T23:31:36.023+0000] {standard_task_runner.py:90} INFO - Running: ['***', 'tasks', 'run', 'pipeline', 'transform', 'manual__2024-04-23T23:06:35.131251+00:00', '--job-id', '61', '--raw', '--subdir', 'DAGS_FOLDER/air_quality/air_quality_dag.py', '--cfg-path', '/tmp/tmp82samh79']
[2024-04-23T23:31:36.025+0000] {standard_task_runner.py:63} INFO - Started process 818 to run task
[2024-04-23T23:31:36.025+0000] {standard_task_runner.py:91} INFO - Job 61: Subtask transform
[2024-04-23T23:31:36.058+0000] {task_command.py:426} INFO - Running <TaskInstance: pipeline.transform manual__2024-04-23T23:06:35.131251+00:00 [running]> on host 8e318e51dc55
[2024-04-23T23:31:36.121+0000] {taskinstance.py:2644} INFO - Exporting env vars: AIRFLOW_CTX_DAG_OWNER='***' AIRFLOW_CTX_DAG_ID='pipeline' AIRFLOW_CTX_TASK_ID='transform' AIRFLOW_CTX_EXECUTION_DATE='2024-04-23T23:06:35.131251+00:00' AIRFLOW_CTX_TRY_NUMBER='5' AIRFLOW_CTX_DAG_RUN_ID='manual__2024-04-23T23:06:35.131251+00:00'
[2024-04-23T23:31:36.121+0000] {taskinstance.py:430} INFO - ::endgroup::
[2024-04-23T23:31:36.145+0000] {taskinstance.py:441} INFO - ::group::Post task execution logs
[2024-04-23T23:31:36.146+0000] {taskinstance.py:2890} ERROR - Task failed with exception
Traceback (most recent call last):
  File "/home/airflow/.local/lib/python3.12/site-packages/airflow/models/taskinstance.py", line 465, in _execute_task
    result = _execute_callable(context=context, **execute_callable_kwargs)
             ^^^^^^^^^^^^^^^^^^^^^^^^^^^^^^^^^^^^^^^^^^^^^^^^^^^^^^^^^^^^^
  File "/home/airflow/.local/lib/python3.12/site-packages/airflow/models/taskinstance.py", line 432, in _execute_callable
    return execute_callable(context=context, **execute_callable_kwargs)
           ^^^^^^^^^^^^^^^^^^^^^^^^^^^^^^^^^^^^^^^^^^^^^^^^^^^^^^^^^^^^
  File "/home/airflow/.local/lib/python3.12/site-packages/airflow/models/baseoperator.py", line 400, in wrapper
    return func(self, *args, **kwargs)
           ^^^^^^^^^^^^^^^^^^^^^^^^^^^
  File "/home/airflow/.local/lib/python3.12/site-packages/airflow/operators/python.py", line 235, in execute
    return_value = self.execute_callable()
                   ^^^^^^^^^^^^^^^^^^^^^^^
  File "/home/airflow/.local/lib/python3.12/site-packages/airflow/operators/python.py", line 252, in execute_callable
    return self.python_callable(*self.op_args, **self.op_kwargs)
           ^^^^^^^^^^^^^^^^^^^^^^^^^^^^^^^^^^^^^^^^^^^^^^^^^^^^^
  File "/opt/airflow/dags/air_quality/tasks.py", line 39, in transform
    df_merged = pd.merge(df_location_transformed, df_air_quality_transformed, on="lat", how="inner")
                ^^^^^^^^^^^^^^^^^^^^^^^^^^^^^^^^^^^^^^^^^^^^^^^^^^^^^^^^^^^^^^^^^^^^^^^^^^^^^^^^^^^^
  File "/home/airflow/.local/lib/python3.12/site-packages/pandas/core/reshape/merge.py", line 169, in merge
    op = _MergeOperation(
         ^^^^^^^^^^^^^^^^
  File "/home/airflow/.local/lib/python3.12/site-packages/pandas/core/reshape/merge.py", line 791, in __init__
    ) = self._get_merge_keys()
        ^^^^^^^^^^^^^^^^^^^^^^
  File "/home/airflow/.local/lib/python3.12/site-packages/pandas/core/reshape/merge.py", line 1269, in _get_merge_keys
    right_keys.append(right._get_label_or_level_values(rk))
                      ^^^^^^^^^^^^^^^^^^^^^^^^^^^^^^^^^^^^
  File "/home/airflow/.local/lib/python3.12/site-packages/pandas/core/generic.py", line 1844, in _get_label_or_level_values
    raise KeyError(key)
KeyError: 'lat'
[2024-04-23T23:31:36.156+0000] {taskinstance.py:1205} INFO - Marking task as FAILED. dag_id=pipeline, task_id=transform, execution_date=20240423T230635, start_date=20240423T233135, end_date=20240423T233136
[2024-04-23T23:31:36.162+0000] {standard_task_runner.py:110} ERROR - Failed to execute job 61 for task transform ('lat'; 818)
[2024-04-23T23:31:36.198+0000] {local_task_job_runner.py:240} INFO - Task exited with return code 1
[2024-04-23T23:31:36.213+0000] {taskinstance.py:3482} INFO - 0 downstream tasks scheduled from follow-on schedule check
[2024-04-23T23:31:36.217+0000] {local_task_job_runner.py:222} INFO - ::endgroup::
