[2024-04-23T23:34:28.018+0000] {local_task_job_runner.py:120} INFO - ::group::Pre task execution logs
[2024-04-23T23:34:28.039+0000] {taskinstance.py:2073} INFO - Dependencies all met for dep_context=non-requeueable deps ti=<TaskInstance: pipeline.transform manual__2024-04-23T23:06:35.131251+00:00 [queued]>
[2024-04-23T23:34:28.174+0000] {taskinstance.py:2073} INFO - Dependencies all met for dep_context=requeueable deps ti=<TaskInstance: pipeline.transform manual__2024-04-23T23:06:35.131251+00:00 [queued]>
[2024-04-23T23:34:28.174+0000] {taskinstance.py:2303} INFO - Starting attempt 7 of 7
[2024-04-23T23:34:28.182+0000] {taskinstance.py:2327} INFO - Executing <Task(PythonOperator): transform> on 2024-04-23 23:06:35.131251+00:00
[2024-04-23T23:34:28.192+0000] {standard_task_runner.py:90} INFO - Running: ['***', 'tasks', 'run', 'pipeline', 'transform', 'manual__2024-04-23T23:06:35.131251+00:00', '--job-id', '63', '--raw', '--subdir', 'DAGS_FOLDER/air_quality/air_quality_dag.py', '--cfg-path', '/tmp/tmp55hqn7af']
[2024-04-23T23:34:28.194+0000] {logging_mixin.py:188} WARNING - /home/***/.local/lib/python3.12/site-packages/***/task/task_runner/standard_task_runner.py:61 DeprecationWarning: This process (pid=892) is multi-threaded, use of fork() may lead to deadlocks in the child.
[2024-04-23T23:34:28.194+0000] {standard_task_runner.py:63} INFO - Started process 896 to run task
[2024-04-23T23:34:28.194+0000] {standard_task_runner.py:91} INFO - Job 63: Subtask transform
[2024-04-23T23:34:28.224+0000] {task_command.py:426} INFO - Running <TaskInstance: pipeline.transform manual__2024-04-23T23:06:35.131251+00:00 [running]> on host 8e318e51dc55
[2024-04-23T23:34:28.282+0000] {taskinstance.py:2644} INFO - Exporting env vars: AIRFLOW_CTX_DAG_OWNER='***' AIRFLOW_CTX_DAG_ID='pipeline' AIRFLOW_CTX_TASK_ID='transform' AIRFLOW_CTX_EXECUTION_DATE='2024-04-23T23:06:35.131251+00:00' AIRFLOW_CTX_TRY_NUMBER='7' AIRFLOW_CTX_DAG_RUN_ID='manual__2024-04-23T23:06:35.131251+00:00'
[2024-04-23T23:34:28.282+0000] {taskinstance.py:430} INFO - ::endgroup::
[2024-04-23T23:34:28.308+0000] {taskinstance.py:441} INFO - ::group::Post task execution logs
[2024-04-23T23:34:28.309+0000] {taskinstance.py:2890} ERROR - Task failed with exception
Traceback (most recent call last):
  File "/home/airflow/.local/lib/python3.12/site-packages/airflow/models/taskinstance.py", line 465, in _execute_task
    result = _execute_callable(context=context, **execute_callable_kwargs)
             ^^^^^^^^^^^^^^^^^^^^^^^^^^^^^^^^^^^^^^^^^^^^^^^^^^^^^^^^^^^^^
  File "/home/airflow/.local/lib/python3.12/site-packages/airflow/models/taskinstance.py", line 432, in _execute_callable
    return execute_callable(context=context, **execute_callable_kwargs)
           ^^^^^^^^^^^^^^^^^^^^^^^^^^^^^^^^^^^^^^^^^^^^^^^^^^^^^^^^^^^^
  File "/home/airflow/.local/lib/python3.12/site-packages/airflow/models/baseoperator.py", line 400, in wrapper
    return func(self, *args, **kwargs)
           ^^^^^^^^^^^^^^^^^^^^^^^^^^^
  File "/home/airflow/.local/lib/python3.12/site-packages/airflow/operators/python.py", line 235, in execute
    return_value = self.execute_callable()
                   ^^^^^^^^^^^^^^^^^^^^^^^
  File "/home/airflow/.local/lib/python3.12/site-packages/airflow/operators/python.py", line 252, in execute_callable
    return self.python_callable(*self.op_args, **self.op_kwargs)
           ^^^^^^^^^^^^^^^^^^^^^^^^^^^^^^^^^^^^^^^^^^^^^^^^^^^^^
  File "/opt/airflow/dags/air_quality/tasks.py", line 42, in transform
    df_selected_columns = df_merged[LIST_COLUMN_NAMES]
                          ~~~~~~~~~^^^^^^^^^^^^^^^^^^^
  File "/home/airflow/.local/lib/python3.12/site-packages/pandas/core/frame.py", line 3899, in __getitem__
    indexer = self.columns._get_indexer_strict(key, "columns")[1]
              ^^^^^^^^^^^^^^^^^^^^^^^^^^^^^^^^^^^^^^^^^^^^^^^^
  File "/home/airflow/.local/lib/python3.12/site-packages/pandas/core/indexes/base.py", line 6114, in _get_indexer_strict
    self._raise_if_missing(keyarr, indexer, axis_name)
  File "/home/airflow/.local/lib/python3.12/site-packages/pandas/core/indexes/base.py", line 6178, in _raise_if_missing
    raise KeyError(f"{not_found} not in index")
KeyError: "['load_datetime'] not in index"
[2024-04-23T23:34:28.318+0000] {taskinstance.py:1205} INFO - Marking task as FAILED. dag_id=pipeline, task_id=transform, execution_date=20240423T230635, start_date=20240423T233428, end_date=20240423T233428
[2024-04-23T23:34:28.324+0000] {standard_task_runner.py:110} ERROR - Failed to execute job 63 for task transform ("['load_datetime'] not in index"; 896)
[2024-04-23T23:34:28.369+0000] {local_task_job_runner.py:240} INFO - Task exited with return code 1
[2024-04-23T23:34:28.384+0000] {taskinstance.py:3482} INFO - 0 downstream tasks scheduled from follow-on schedule check
[2024-04-23T23:34:28.388+0000] {local_task_job_runner.py:222} INFO - ::endgroup::
