[2024-04-23T23:30:17.196+0000] {local_task_job_runner.py:120} INFO - ::group::Pre task execution logs
[2024-04-23T23:30:17.218+0000] {taskinstance.py:2073} INFO - Dependencies all met for dep_context=non-requeueable deps ti=<TaskInstance: pipeline.transform manual__2024-04-23T23:06:35.131251+00:00 [queued]>
[2024-04-23T23:30:17.348+0000] {taskinstance.py:2073} INFO - Dependencies all met for dep_context=requeueable deps ti=<TaskInstance: pipeline.transform manual__2024-04-23T23:06:35.131251+00:00 [queued]>
[2024-04-23T23:30:17.348+0000] {taskinstance.py:2303} INFO - Starting attempt 4 of 4
[2024-04-23T23:30:17.357+0000] {taskinstance.py:2327} INFO - Executing <Task(PythonOperator): transform> on 2024-04-23 23:06:35.131251+00:00
[2024-04-23T23:30:17.369+0000] {logging_mixin.py:188} WARNING - /home/***/.local/lib/python3.12/site-packages/***/task/task_runner/standard_task_runner.py:61 DeprecationWarning: This process (pid=777) is multi-threaded, use of fork() may lead to deadlocks in the child.
[2024-04-23T23:30:17.367+0000] {standard_task_runner.py:90} INFO - Running: ['***', 'tasks', 'run', 'pipeline', 'transform', 'manual__2024-04-23T23:06:35.131251+00:00', '--job-id', '60', '--raw', '--subdir', 'DAGS_FOLDER/air_quality/air_quality_dag.py', '--cfg-path', '/tmp/tmpqlqpb8xw']
[2024-04-23T23:30:17.369+0000] {standard_task_runner.py:63} INFO - Started process 779 to run task
[2024-04-23T23:30:17.369+0000] {standard_task_runner.py:91} INFO - Job 60: Subtask transform
[2024-04-23T23:30:17.400+0000] {task_command.py:426} INFO - Running <TaskInstance: pipeline.transform manual__2024-04-23T23:06:35.131251+00:00 [running]> on host 8e318e51dc55
[2024-04-23T23:30:17.458+0000] {taskinstance.py:2644} INFO - Exporting env vars: AIRFLOW_CTX_DAG_OWNER='***' AIRFLOW_CTX_DAG_ID='pipeline' AIRFLOW_CTX_TASK_ID='transform' AIRFLOW_CTX_EXECUTION_DATE='2024-04-23T23:06:35.131251+00:00' AIRFLOW_CTX_TRY_NUMBER='4' AIRFLOW_CTX_DAG_RUN_ID='manual__2024-04-23T23:06:35.131251+00:00'
[2024-04-23T23:30:17.458+0000] {taskinstance.py:430} INFO - ::endgroup::
[2024-04-23T23:30:17.482+0000] {taskinstance.py:441} INFO - ::group::Post task execution logs
[2024-04-23T23:30:17.483+0000] {taskinstance.py:2890} ERROR - Task failed with exception
Traceback (most recent call last):
  File "/home/airflow/.local/lib/python3.12/site-packages/airflow/models/taskinstance.py", line 465, in _execute_task
    result = _execute_callable(context=context, **execute_callable_kwargs)
             ^^^^^^^^^^^^^^^^^^^^^^^^^^^^^^^^^^^^^^^^^^^^^^^^^^^^^^^^^^^^^
  File "/home/airflow/.local/lib/python3.12/site-packages/airflow/models/taskinstance.py", line 432, in _execute_callable
    return execute_callable(context=context, **execute_callable_kwargs)
           ^^^^^^^^^^^^^^^^^^^^^^^^^^^^^^^^^^^^^^^^^^^^^^^^^^^^^^^^^^^^
  File "/home/airflow/.local/lib/python3.12/site-packages/airflow/models/baseoperator.py", line 400, in wrapper
    return func(self, *args, **kwargs)
           ^^^^^^^^^^^^^^^^^^^^^^^^^^^
  File "/home/airflow/.local/lib/python3.12/site-packages/airflow/operators/python.py", line 235, in execute
    return_value = self.execute_callable()
                   ^^^^^^^^^^^^^^^^^^^^^^^
  File "/home/airflow/.local/lib/python3.12/site-packages/airflow/operators/python.py", line 252, in execute_callable
    return self.python_callable(*self.op_args, **self.op_kwargs)
           ^^^^^^^^^^^^^^^^^^^^^^^^^^^^^^^^^^^^^^^^^^^^^^^^^^^^^
  File "/opt/airflow/dags/air_quality/tasks.py", line 36, in transform
    df_air_quality_transformed = air_quality_connector.transform_air_quality()
                                 ^^^^^^^^^^^^^^^^^^^^^^^^^^^^^^^^^^^^^^^^^^^^^
  File "/opt/airflow/src/AirQualityConnector.py", line 110, in transform_air_quality
    df_air.columns = LIST_COLUMN_NAMES
    ^^^^^^^^^^^^^^
  File "/home/airflow/.local/lib/python3.12/site-packages/pandas/core/generic.py", line 6218, in __setattr__
    return object.__setattr__(self, name, value)
           ^^^^^^^^^^^^^^^^^^^^^^^^^^^^^^^^^^^^^
  File "properties.pyx", line 69, in pandas._libs.properties.AxisProperty.__set__
  File "/home/airflow/.local/lib/python3.12/site-packages/pandas/core/generic.py", line 767, in _set_axis
    self._mgr.set_axis(axis, labels)
  File "/home/airflow/.local/lib/python3.12/site-packages/pandas/core/internals/managers.py", line 227, in set_axis
    self._validate_set_axis(axis, new_labels)
  File "/home/airflow/.local/lib/python3.12/site-packages/pandas/core/internals/base.py", line 85, in _validate_set_axis
    raise ValueError(
ValueError: Length mismatch: Expected axis has 11 elements, new values have 17 elements
[2024-04-23T23:30:17.491+0000] {taskinstance.py:1205} INFO - Marking task as FAILED. dag_id=pipeline, task_id=transform, execution_date=20240423T230635, start_date=20240423T233017, end_date=20240423T233017
[2024-04-23T23:30:17.497+0000] {standard_task_runner.py:110} ERROR - Failed to execute job 60 for task transform (Length mismatch: Expected axis has 11 elements, new values have 17 elements; 779)
[2024-04-23T23:30:17.542+0000] {local_task_job_runner.py:240} INFO - Task exited with return code 1
[2024-04-23T23:30:17.557+0000] {taskinstance.py:3482} INFO - 0 downstream tasks scheduled from follow-on schedule check
[2024-04-23T23:30:17.560+0000] {local_task_job_runner.py:222} INFO - ::endgroup::
