[2024-04-26T18:05:27.860+0000] {local_task_job_runner.py:120} INFO - ::group::Pre task execution logs
[2024-04-26T18:05:27.883+0000] {taskinstance.py:2073} INFO - Dependencies all met for dep_context=non-requeueable deps ti=<TaskInstance: air_quality_pipeline.send_air_quality_alerts manual__2024-04-26T18:04:10.972377+00:00 [queued]>
[2024-04-26T18:05:28.007+0000] {taskinstance.py:2073} INFO - Dependencies all met for dep_context=requeueable deps ti=<TaskInstance: air_quality_pipeline.send_air_quality_alerts manual__2024-04-26T18:04:10.972377+00:00 [queued]>
[2024-04-26T18:05:28.008+0000] {taskinstance.py:2303} INFO - Starting attempt 1 of 2
[2024-04-26T18:05:28.017+0000] {taskinstance.py:2327} INFO - Executing <Task(PythonOperator): send_air_quality_alerts> on 2024-04-26 18:04:10.972377+00:00
[2024-04-26T18:05:28.028+0000] {standard_task_runner.py:90} INFO - Running: ['***', 'tasks', 'run', 'air_quality_pipeline', 'send_air_quality_alerts', 'manual__2024-04-26T18:04:10.972377+00:00', '--job-id', '416', '--raw', '--subdir', 'DAGS_FOLDER/air_quality/air_quality_dag.py', '--cfg-path', '/tmp/tmp_gph21to']
[2024-04-26T18:05:28.030+0000] {standard_task_runner.py:91} INFO - Job 416: Subtask send_air_quality_alerts
[2024-04-26T18:05:28.031+0000] {logging_mixin.py:188} WARNING - /home/***/.local/lib/python3.12/site-packages/***/task/task_runner/standard_task_runner.py:61 DeprecationWarning: This process (pid=2438) is multi-threaded, use of fork() may lead to deadlocks in the child.
[2024-04-26T18:05:28.032+0000] {standard_task_runner.py:63} INFO - Started process 2440 to run task
[2024-04-26T18:05:28.061+0000] {task_command.py:426} INFO - Running <TaskInstance: air_quality_pipeline.send_air_quality_alerts manual__2024-04-26T18:04:10.972377+00:00 [running]> on host 5fdceac7b2c7
[2024-04-26T18:05:28.124+0000] {taskinstance.py:2644} INFO - Exporting env vars: AIRFLOW_CTX_DAG_OWNER='***' AIRFLOW_CTX_DAG_ID='air_quality_pipeline' AIRFLOW_CTX_TASK_ID='send_air_quality_alerts' AIRFLOW_CTX_EXECUTION_DATE='2024-04-26T18:04:10.972377+00:00' AIRFLOW_CTX_TRY_NUMBER='1' AIRFLOW_CTX_DAG_RUN_ID='manual__2024-04-26T18:04:10.972377+00:00'
[2024-04-26T18:05:28.124+0000] {taskinstance.py:430} INFO - ::endgroup::
[2024-04-26T18:05:28.133+0000] {tasks.py:94} INFO - Generating air quality alerts...
[2024-04-26T18:05:28.141+0000] {taskinstance.py:441} INFO - ::group::Post task execution logs
[2024-04-26T18:05:28.141+0000] {taskinstance.py:2890} ERROR - Task failed with exception
Traceback (most recent call last):
  File "/home/airflow/.local/lib/python3.12/site-packages/airflow/models/taskinstance.py", line 465, in _execute_task
    result = _execute_callable(context=context, **execute_callable_kwargs)
             ^^^^^^^^^^^^^^^^^^^^^^^^^^^^^^^^^^^^^^^^^^^^^^^^^^^^^^^^^^^^^
  File "/home/airflow/.local/lib/python3.12/site-packages/airflow/models/taskinstance.py", line 432, in _execute_callable
    return execute_callable(context=context, **execute_callable_kwargs)
           ^^^^^^^^^^^^^^^^^^^^^^^^^^^^^^^^^^^^^^^^^^^^^^^^^^^^^^^^^^^^
  File "/home/airflow/.local/lib/python3.12/site-packages/airflow/models/baseoperator.py", line 400, in wrapper
    return func(self, *args, **kwargs)
           ^^^^^^^^^^^^^^^^^^^^^^^^^^^
  File "/home/airflow/.local/lib/python3.12/site-packages/airflow/operators/python.py", line 235, in execute
    return_value = self.execute_callable()
                   ^^^^^^^^^^^^^^^^^^^^^^^
  File "/home/airflow/.local/lib/python3.12/site-packages/airflow/operators/python.py", line 252, in execute_callable
    return self.python_callable(*self.op_args, **self.op_kwargs)
           ^^^^^^^^^^^^^^^^^^^^^^^^^^^^^^^^^^^^^^^^^^^^^^^^^^^^^
  File "/opt/airflow/dags/air_quality/tasks.py", line 95, in send_air_quality_alerts
    alert_message = air_quality_alerts()
                    ^^^^^^^^^^^^^^^^^^^^
  File "/opt/airflow/src/air_quality_alerts.py", line 72, in air_quality_alerts
    alerts = generate_alerts(data, config)
             ^^^^^^^^^^^^^^^^^^^^^^^^^^^^^
  File "/opt/airflow/src/air_quality_alerts.py", line 47, in generate_alerts
    for city, value, timestamp in city_data[["city_name", contaminant, "measurement_hour"]].values:
                                  ~~~~~~~~~^^^^^^^^^^^^^^^^^^^^^^^^^^^^^^^^^^^^^^^^^^^^^^^^
  File "/home/airflow/.local/lib/python3.12/site-packages/pandas/core/frame.py", line 3899, in __getitem__
    indexer = self.columns._get_indexer_strict(key, "columns")[1]
              ^^^^^^^^^^^^^^^^^^^^^^^^^^^^^^^^^^^^^^^^^^^^^^^^
  File "/home/airflow/.local/lib/python3.12/site-packages/pandas/core/indexes/base.py", line 6114, in _get_indexer_strict
    self._raise_if_missing(keyarr, indexer, axis_name)
  File "/home/airflow/.local/lib/python3.12/site-packages/pandas/core/indexes/base.py", line 6178, in _raise_if_missing
    raise KeyError(f"{not_found} not in index")
KeyError: "['co'] not in index"
[2024-04-26T18:05:28.151+0000] {taskinstance.py:1205} INFO - Marking task as UP_FOR_RETRY. dag_id=air_quality_pipeline, task_id=send_air_quality_alerts, execution_date=20240426T180410, start_date=20240426T180527, end_date=20240426T180528
[2024-04-26T18:05:28.158+0000] {standard_task_runner.py:110} ERROR - Failed to execute job 416 for task send_air_quality_alerts ("['co'] not in index"; 2440)
[2024-04-26T18:05:28.205+0000] {local_task_job_runner.py:240} INFO - Task exited with return code 1
[2024-04-26T18:05:28.220+0000] {taskinstance.py:3482} INFO - 0 downstream tasks scheduled from follow-on schedule check
[2024-04-26T18:05:28.222+0000] {local_task_job_runner.py:222} INFO - ::endgroup::
