[2024-04-25T23:19:10.158+0000] {local_task_job_runner.py:120} INFO - ::group::Pre task execution logs
[2024-04-25T23:19:10.182+0000] {taskinstance.py:2073} INFO - Dependencies all met for dep_context=non-requeueable deps ti=<TaskInstance: pipeline.etl.transform manual__2024-04-25T22:52:20.828871+00:00 [queued]>
[2024-04-25T23:19:10.322+0000] {taskinstance.py:2073} INFO - Dependencies all met for dep_context=requeueable deps ti=<TaskInstance: pipeline.etl.transform manual__2024-04-25T22:52:20.828871+00:00 [queued]>
[2024-04-25T23:19:10.322+0000] {taskinstance.py:2303} INFO - Starting attempt 1 of 1
[2024-04-25T23:19:10.332+0000] {taskinstance.py:2327} INFO - Executing <Task(PythonOperator): etl.transform> on 2024-04-25 22:52:20.828871+00:00
[2024-04-25T23:19:10.341+0000] {logging_mixin.py:188} WARNING - /home/***/.local/lib/python3.12/site-packages/***/task/task_runner/standard_task_runner.py:61 DeprecationWarning: This process (pid=4701) is multi-threaded, use of fork() may lead to deadlocks in the child.
[2024-04-25T23:19:10.342+0000] {standard_task_runner.py:63} INFO - Started process 4706 to run task
[2024-04-25T23:19:10.342+0000] {standard_task_runner.py:90} INFO - Running: ['***', 'tasks', 'run', 'pipeline', 'etl.transform', 'manual__2024-04-25T22:52:20.828871+00:00', '--job-id', '201', '--raw', '--subdir', 'DAGS_FOLDER/air_quality/air_quality_dag.py', '--cfg-path', '/tmp/tmpjuttn43k']
[2024-04-25T23:19:10.344+0000] {standard_task_runner.py:91} INFO - Job 201: Subtask etl.transform
[2024-04-25T23:19:10.379+0000] {task_command.py:426} INFO - Running <TaskInstance: pipeline.etl.transform manual__2024-04-25T22:52:20.828871+00:00 [running]> on host cf1d83d83b27
[2024-04-25T23:19:10.449+0000] {taskinstance.py:2644} INFO - Exporting env vars: AIRFLOW_CTX_DAG_OWNER='***' AIRFLOW_CTX_DAG_ID='pipeline' AIRFLOW_CTX_TASK_ID='etl.transform' AIRFLOW_CTX_EXECUTION_DATE='2024-04-25T22:52:20.828871+00:00' AIRFLOW_CTX_TRY_NUMBER='1' AIRFLOW_CTX_DAG_RUN_ID='manual__2024-04-25T22:52:20.828871+00:00'
[2024-04-25T23:19:10.450+0000] {taskinstance.py:430} INFO - ::endgroup::
[2024-04-25T23:19:10.460+0000] {taskinstance.py:441} INFO - ::group::Post task execution logs
[2024-04-25T23:19:10.460+0000] {taskinstance.py:2890} ERROR - Task failed with exception
Traceback (most recent call last):
  File "/home/airflow/.local/lib/python3.12/site-packages/airflow/models/taskinstance.py", line 465, in _execute_task
    result = _execute_callable(context=context, **execute_callable_kwargs)
             ^^^^^^^^^^^^^^^^^^^^^^^^^^^^^^^^^^^^^^^^^^^^^^^^^^^^^^^^^^^^^
  File "/home/airflow/.local/lib/python3.12/site-packages/airflow/models/taskinstance.py", line 432, in _execute_callable
    return execute_callable(context=context, **execute_callable_kwargs)
           ^^^^^^^^^^^^^^^^^^^^^^^^^^^^^^^^^^^^^^^^^^^^^^^^^^^^^^^^^^^^
  File "/home/airflow/.local/lib/python3.12/site-packages/airflow/models/baseoperator.py", line 400, in wrapper
    return func(self, *args, **kwargs)
           ^^^^^^^^^^^^^^^^^^^^^^^^^^^
  File "/home/airflow/.local/lib/python3.12/site-packages/airflow/operators/python.py", line 235, in execute
    return_value = self.execute_callable()
                   ^^^^^^^^^^^^^^^^^^^^^^^
  File "/home/airflow/.local/lib/python3.12/site-packages/airflow/operators/python.py", line 252, in execute_callable
    return self.python_callable(*self.op_args, **self.op_kwargs)
           ^^^^^^^^^^^^^^^^^^^^^^^^^^^^^^^^^^^^^^^^^^^^^^^^^^^^^
  File "/opt/airflow/dags/air_quality/tasks.py", line 39, in transform
    df_location_transformed = location_connector.transform_location()
                              ^^^^^^^^^^^^^^^^^^^^^^^^^^^^^^^^^^^^^^^
  File "/opt/airflow/src/LocationConnector.py", line 92, in transform_location
    df = pd.read_json("location_data.json")
         ^^^^^^^^^^^^^^^^^^^^^^^^^^^^^^^^^^
  File "/home/airflow/.local/lib/python3.12/site-packages/pandas/io/json/_json.py", line 780, in read_json
    json_reader = JsonReader(
                  ^^^^^^^^^^^
  File "/home/airflow/.local/lib/python3.12/site-packages/pandas/io/json/_json.py", line 893, in __init__
    data = self._get_data_from_filepath(filepath_or_buffer)
           ^^^^^^^^^^^^^^^^^^^^^^^^^^^^^^^^^^^^^^^^^^^^^^^^
  File "/home/airflow/.local/lib/python3.12/site-packages/pandas/io/json/_json.py", line 949, in _get_data_from_filepath
    raise FileNotFoundError(f"File {filepath_or_buffer} does not exist")
FileNotFoundError: File location_data.json does not exist
[2024-04-25T23:19:10.469+0000] {taskinstance.py:1205} INFO - Marking task as FAILED. dag_id=pipeline, task_id=etl.transform, execution_date=20240425T225220, start_date=20240425T231910, end_date=20240425T231910
[2024-04-25T23:19:10.475+0000] {standard_task_runner.py:110} ERROR - Failed to execute job 201 for task etl.transform (File location_data.json does not exist; 4706)
[2024-04-25T23:19:10.515+0000] {local_task_job_runner.py:240} INFO - Task exited with return code 1
[2024-04-25T23:19:10.533+0000] {taskinstance.py:3482} INFO - 0 downstream tasks scheduled from follow-on schedule check
[2024-04-25T23:19:10.534+0000] {local_task_job_runner.py:222} INFO - ::endgroup::
